Workbook

Sheet CAPA
B2: Modelo Looker - Oficial Português
B3: Modelo Looker - Oficial Inglês
B4: 1. Prompt Alinhamento
B5: 2. Prompt Entrevista
B6: 3. Prompt Shortlist
B8: Modelo Looker Decision Framework
B9: 4. Prompt Tomada de Decisão

Sheet Alinhamento
C2: NOME EMPRESA | D2: POSIÇÃO
B3: A COMPANHIA | C3: | ESTRUTURA DA EMPRESA | A Saipos foi fundada em 2017 e é o segundo empreendimento dos sócios. Anteriormente, eles fundaram a Devorando, vendida ao iFood em 2016. A estrutura executiva é composta por quatro founders, sendo três deles C-level. Kenner Grings é o responsável por Produto, Tecnologia e Suporte. Anderson é o CRO, e Bruno é o CEO, olhando para People, Financeiro, Implantação e CS. A empresa tem cerca de 13.000 clientes atualmente, com a meta de alcançar 22.000 a 24.000 clientes até março do próximo ano. O iFood é o acionista majoritário após um novo aporte, mas a Saipos mantém autonomia operacional significativa. | | :--- | :--- | | SETOR, CONCORRÊNCIA E DIFERENCIAIS COMPETITIVOS | A Saipos atua no setor de food service, fornecendo software de gestão e operação (PDV e ERP) para restaurantes, focando na "porta para dentro" do negócio. O mercado é altamente fragmentado no Brasil, com cerca de 1,2 milhão de restaurantes e muitos players regionais. A Saipos se posiciona como um potencial novo líder de mercado (visando atender 100.000 restaurantes). A concorrência inclui Links, Totus, Colibri, Consumer, Yoga, Cardápio Web e Vuca Delivery. Os diferenciais competitivos são: ser um sistema 100% em nuvem/online (capilaridade nacional), ser o maior integrador de pedidos do iFood no Brasil (10% dos pedidos passam pelo PDV da Saipos), e ter mais de 70 ferramentas. O público-alvo (ICP) são restaurantes que faturam entre R$ 70.000 e R$ 500.000. | | MOMENTO / CONTEXTO DA EMPRESA | A empresa vive um momento de crescimento acelerado e expansão, impulsionado pelo novo aporte e pela entrada do iFood como acionista majoritário. O desafio central que gerou a posição é a necessidade de reduzir o churn e transformar a área de suporte de um centro de custo para uma área de promoção da empresa, reconhecida pela qualidade do atendimento. | | PRINCIPAIS DESAFIOS ATUAIS DA EMPRESA | O principal desafio estratégico é atingir a meta agressiva de crescimento da base de clientes (de 13.000 para 22.000 a 24.000 clientes até março). Isso exige manter a máquina de crescimento aquecida e, simultaneamente, reduzir a taxa de cancelamento (churn) por meio de uma melhor experiência de suporte. | | PRINCIPAIS OBJETIVOS E DESAFIOS DA VAGA | Resultados esperados (os três grandes objetivos) são: reduzir a densidade de chamados (contact rate) de 2.4 para 1.3; alcançar 90% dos acionamentos atendidos em primeira resposta do agente em até 1 minuto (atualmente em 60%); e atingir um CESAT de 98. O objetivo principal é a melhoria contínua, transformando o suporte em um promotor do negócio. As barreiras incluem a necessidade de estruturar a área de dados (dashboards, painéis de acompanhamento) e repensar as métricas e o dimensionamento do time (capacity planning). | | REPORTE DIRETO | Kenner Grings (C-level responsável por Produto, Tecnologia e Suporte). | | EQUIPE | O time de suporte lida com cerca de 25.000 acionamentos por mês, majoritariamente via chat e WhatsApp. A equipe atualmente tem quatro supervisores, com planos de expandir para seis, cobrindo três filas de atendimento (generalista, impressões, integrações e fiscal). Há também um time de backoffice (para demandas que não se resolvem via chat/e-mail) e um time N3 (para bugs e problemas de produto). O time de Qualidade e Treinamento reporta a um supervisor. | | LOCALIDADE | São Leopoldo, RS (Tecnosinos). O time de suporte é híbrido, com estagiários e juniores presenciais obrigatórios. Para a gestão, a preferência é por disponibilidade presencial/híbrida (flexibilização possível após onboarding de 30-60 dias). | | MODELO DE CONTRATAÇÃO | PJ (Pessoa Jurídica). | | SALÁRIO FIXO MENSAL | Faixa salarial de R$ 28.000 (alvo) até R$ 35.000 (para um candidato excepcional), em 12 notas. | | REMUNERAÇÃO VARIÁVEL | Bônus variável de duas vezes o salário (anual), com primeiro gatilho de liberação ativado ao atingir 85% da meta de crescimento de clientes da empresa. Inclui 30 dias de férias remuneradas e plano de saúde. | | EXPERIÊNCIA PROFISSIONAL IDEAL DO EXECUTIVO | Experiência em empresas de RP/SAS de alto volume de atendimento, como Conta Azul, Bling, King Host e Zenvia. Necessita de histórico de desenvolvimento de software em escala, preferencialmente com foco em processos Kanban. Deve ter experiência com suporte a clientes de perfil menos técnico (próximo de B2C) e senso de urgência na resolução de problemas (diferente de e-commerce). Valoriza-se experiência em uso de dados e IA para otimizar atendimento e dimensionamento. | | HISTÓRICO ACADÊMICO IDEAL DO EXECUTIVO | Não foi mencionada uma formação acadêmica específica obrigatória. | | CORE SKILL IDEAL 1 | Competências analíticas. Essencial para estruturar dashboards, métricas e o dimensionamento da equipe de suporte, transformando dados em melhoria contínua e resultados. | | CORE SKILL IDEAL 2 | Proatividade e Iniciativa. Necessário para ser propositivo na implementação de projetos e alternativas que visem atingir as metas agressivas de contact rate e tempo de resposta. | | CORE SKILL IDEAL 3 | Agilidade. Crucial para atuar em um ambiente de alto volume (25k acionamentos/mês) e senso de urgência, garantindo que 90% dos chamados sejam atendidos em 1 minuto. | | REQUISITOS ESPECÍFICOS PARA O EXECUTIVO | Prioridade para disponibilidade presencial/híbrida em São Leopoldo. Experiência em suporte para clientes não-técnicos (proprietários de restaurante/funcionários). Foco em melhoria contínua e resultados. Inglês desejável para documentação. |
B7: A POSIÇÃO
B14: PERFIL IDEAL

Sheet Shortlist
B2: SHORTLIST | C2: CANDIDATO | D2: IDADE | E2: POSIÇÃO ATUAL | F2: LOCALIDADE | G2: HISTÓRICO ACADÊMICO | H2: EXPERIÊNCIA PROFISSIONAL | I2: PRINCIPAIS PROJETOS DA CARREIRA | J2: PACOTE DE REMUNERAÇÃO ATUAL | K2: CORE SKILLS | L2: MOTIVAÇÕES
B3: Candidato 1 | C3: Paulo Ricardo Dauinheimer Machado | D3: N/A | E3: Gerente de Operações | F3: N/A | G3: N/A | H3: META – Gerente de Operações (DEZ/2024 – ATUAL); SPACE7 DIGITAL – CEO e Founder (FEV/2023 – DEZ/2024); LINX – Gerente de Operações (JUN/2018 – FEV/2023); DCG – Gerente de Operações (DEZ/2015 – JUN/2018); EZ COMMERCE – Coordenador de Equipe (JAN/2015 – DEZ/2015); Stefanini (Estágio a Líder de Equipe): Cinco anos, saiu liderando 25 pessoas em suporte puro de TI Nível 2. | I3: 1. Estruturação de Indicadores e KPIs do Zero: Na startup de e-commerce (EZ/DCG), implementou o Zendesk e criou métricas de performance e bases analíticas do zero, estruturando o suporte para o crescimento subsequente. 2. Recuperação do NPS: Coordenou um plano de ação colaborativo entre Operações e Produto após feedback negativo (devido à descontinuação de um produto), revertendo o NPS de um patamar negativo para 50-60 em cerca de um ano e meio. 3. Gestão de Crise e Liderança na Pandemia: Durante o crescimento de demanda do e-commerce, a equipe cresceu de 50 para 80 pessoas. Blindou o time, assumindo responsabilidades em reuniões de War Room. Foi premiado como "Líder do Ano" da Linx em 2021. | J3: CLT: Salário fixo mensal de R$ 14.000, além de ajuda de custo e dois salários anuais. Benefícios incluem Plano de Saúde/Odontológico, Vale Refeição/Alimentação e Auxílio Educação/Creche. | K3: Liderança e Influência social: Evidenciada pelo reconhecimento como "Líder do Ano" na Linx, conquistado por proteger sua equipe sob pressão (War Room). Competências analíticas/Pensamento sistêmico: Demonstrado na capacidade de estruturar indicadores, KPIs e NPS do zero na startup. Proatividade e Iniciativa: Evidenciada na implementação de ITIL e Zendesk em ambientes com ausência de processos. | L3: Busca uma oportunidade mais alinhada com sua visão cultural, diferente do perfil tradicional da Meta. Almeja desafios estratégicos em um cenário de crescimento exponencial e deseja participar ativamente das decisões, papel que exerceu anteriormente.
B4: Candidato 2 | C4: Saul Souza | D4: 31 | E4: Gerente de Tecnologia e Desenvolvimento (DI MARMORE) e Gerente de Suporte Técnico (ISYSTEMS) | F4: Taboão da Serra / SP | G4: PONTIFÍCIA UNIVERSIDADE CATÓLICA DO RS (PUCRS) – MBA em Gestão de Projetos (2025 – ATUAL); UNIVERSIDADE ANHEMBI MORUMBI (UAM) – Graduação em Gestão de TI (2019 – 2021) | H4: DI MARMORE – Gerente de Tecnologia e Desenvolvimento (JUL/2025 – ATUAL); ISYSTEMS – Gerente de Suporte Técnico (DEZ/2023 – ATUAL); OMIE – Gerente de Suporte Técnico (DEZ/2017 – SET/2023) | I4: 1. Restruturação da Área de Suporte na OMIE: Estruturou cargos (Estagiário, N1, N2, N3) e departamentos (Qualidade, Treinamento), escalando a operação de 20.000 para 70.000 chamados/mês e alcançando 98% de CSAT pelo terceiro ano consecutivo. 2. Criação do Departamento de Treinamento na OMIE: Implementou uma "universidade" de suporte para reduzir a rampagem do analista de 2 anos para 6 meses. 3. Transformação do Suporte e Aumento da Taxa de Uso na ISYSTEMS: Reformulou o suporte técnico, focando na taxa de uso do software de controle avançado. Resultado: Atingiu 79% de taxa de uso, o maior índice na história da empresa. | J4: Regime PJ. Salário Fixo Mensal R$ 20.000,00. Bônus Anual Target último ano – R$ 1.000,00. Benefícios: Plano de Saúde / Odontológico Bradesco Nacional; Vale Refeição / Alimentação R$ 950,00; Veículo Corporativo (Aluguel custeado); Auxílio Educação (Pós-graduação R$ 400,00 + Idiomas R$ 175,00). | K4: Liderança e Influência social: Evidenciado pela gestão de uma equipe de 200 pessoas na OMIE e pela criação de um projeto de team leaders. Visão estratégica: Demonstração ao reformular a estrutura de cargos na OMIE para escalar a área e ao focar na taxa de uso na ISYSTEMS (atingindo 79%). Gestão de Recursos: Criação dos departamentos de Qualidade e Treinamento na OMIE, otimizando processos. Assertividade: Pontuação de 5 em 5. | L4: Retornar à área de suporte em uma empresa em ascensão e forte crescimento (similar ao modelo da OMIE), que ofereça desafios transformacionais. Buscar um ambiente que proporcione oportunidades de aprendizado e proximidade com a liderança sênior. Disposto a realizar uma mudança familiar para o Rio Grande do Sul, caso a oportunidade seja atrativa.

Sheet Dashboard
A1: Candidate ID | B1: Candidato | C1: Organização Atual | D1: Hiring Stage | E1: Salário Atual | F1: Expectativa Salarial | G1: Género | H1: Cidade | I1: Título / Posição | J1: Cargo | K1: Especialidade | L1: Modelo de Contrato | M1: Modelo de trabalho | N1: Remuneração variável (anual) / ICP | O1: Segmento | P1: Stock Options / ILP | Q1: Disposto a mudar de residência | R1: English Proficiency | S1: Rejection Reason | T1: Primeiro Nome | U1: Conversão | V1: Bônus anual (salários) | W1: Remuneração anual | X1: Faixa atual /ano | Y1: Pretensão anual | Z1: Faixa pretensão /ano
A2: TESTE | B2: TESTE | C2: TESTE | D2: Shortlist | E2: 30000 | F2: 30000 | G2: TESTE | H2: TESTE | I2: TESTE | J2: TESTE | K2: TESTE | L2: TESTE | M2: TESTE | N2: 30000 | O2: TESTE | P2: TESTE | Q2: TESTE | R2: TESTE | S2: TESTE | T2: TESTE | U2: =(F2/E2)-1 -> 0 | V2: =ROUNDDOWN(N2/E2,0) -> 1 | W2: =13.33*E2+N2 -> 429900 | X2: =IF(W2<100000,"abaixo de R$100.000",IF(AND(W2>=100000,W2<200000),"R$100.000 - R$200.000",IF(AND(W2>=200000,W2<300000),"R$200.000 - R$300.000",IF(AND(W2>=300000,W2<400000),"R$300.000 - R$400.000",IF(AND(W2>=400000,W2<500000),"R$400.000 - R$500.000",IF(AND(W2>=500000,W2<600000),"R$500.000 - R$600.000",IF(AND(W2>=600000,W2<700000),"R$600.000 - R$700.000",IF(AND(W2>=700000,W2<800000),"R$700.000 - R$800.000",IF(AND(W2>=800000,W2<900000),"R$800.000 - R$900.000",IF(AND(W2>=900000,W2<1000000),"R$900.000 - R$1.000.000","Superior a R$1.000.000")))))))))) -> R$400.000 - R$500.000 | Y2: =W2+(W2*U2) -> 429900 | Z2: =IF(Y2<100000,"abaixo de R$100.000",IF(AND(Y2>=100000,Y2<200000),"R$100.000 - R$200.000",IF(AND(Y2>=200000,Y2<300000),"R$200.000 - R$300.000",IF(AND(Y2>=300000,Y2<400000),"R$300.000 - R$400.000",IF(AND(Y2>=400000,Y2<500000),"R$400.000 - R$500.000",IF(AND(Y2>=500000,Y2<600000),"R$500.000 - R$600.000",IF(AND(Y2>=600000,Y2<700000),"R$600.000 - R$700.000",IF(AND(Y2>=700000,Y2<800000),"R$700.000 - R$800.000",IF(AND(Y2>=800000,Y2<900000),"R$800.000 - R$900.000",IF(AND(Y2>=900000,Y2<1000000),"R$900.000 - R$1.000.000","Superior a R$1.000.000")))))))))) -> R$400.000 - R$500.000

Sheet Remuneração e Risco
B1: Empregador 1 | C1: Pretensão 1 | D1: Cliente 1 | F1: Empregador 2 | G1: Pretensão 2 | H1: Cliente 2 | J1: Empregador 3 | K1: Pretensão 3 | L1: Cliente 3
A2: Base mensal
A3: Salário base mês
A4: Modelo de Contrato | B4: CLT | C4: PJ | D4: RSU | F4: CLT | G4: PJ | H4: RSU | J4: CLT | K4: PJ | L4: RSU
A5: Multiplos de salário | B5: =IF(B4="CLT","13,33",IF(B4="PJ","12",IF(B4="Estatutário","12",IF(B4="RSU","12","NULL")))) -> 13,33 | C5: =IF(C4="CLT","13,33",IF(C4="PJ","12",IF(C4="Estatutário","12",IF(C4="RSU","12","NULL")))) -> 12 | D5: =IF(D4="CLT","13,33",IF(D4="PJ","12",IF(D4="Estatutário","12",IF(D4="RSU","12","NULL")))) -> 12 | F5: =IF(F4="CLT","13,33",IF(F4="PJ","12",IF(F4="Estatutário","12",IF(F4="RSU","12","NULL")))) -> 13,33 | G5: =IF(G4="CLT","13,33",IF(G4="PJ","12",IF(G4="Estatutário","12",IF(G4="RSU","12","NULL")))) -> 12 | H5: =IF(H4="CLT","13,33",IF(H4="PJ","12",IF(H4="Estatutário","12",IF(H4="RSU","12","NULL")))) -> 12 | J5: =IF(J4="CLT","13,33",IF(J4="PJ","12",IF(J4="Estatutário","12",IF(J4="RSU","12","NULL")))) -> 13,33 | K5: =IF(K4="CLT","13,33",IF(K4="PJ","12",IF(K4="Estatutário","12",IF(K4="RSU","12","NULL")))) -> 12 | L5: =IF(L4="CLT","13,33",IF(L4="PJ","12",IF(L4="Estatutário","12",IF(L4="RSU","12","NULL")))) -> 12
A6: Múltiplos de salários de bônus
A7: Base anual
A8: Remuneração fixa | B8: =B3*B5 -> 0 | C8: =C3*C5 -> 0 | D8: =D3*D5 -> 0 | F8: =F3*F5 -> 0 | G8: =G3*G5 -> 0 | H8: =H3*H5 -> 0 | J8: =J3*J5 -> 0 | K8: =K3*K5 -> 0 | L8: =L3*L5 -> 0
A9: Bônus | ICP | B9: =B6*B3 -> 0 | C9: =C6*C3 -> 0 | D9: =D6*D3 -> 0 | F9: =F6*F3 -> 0 | G9: =G6*G3 -> 0 | H9: =H6*H3 -> 0 | J9: =J6*J3 -> 0 | K9: =K6*K3 -> 0 | L9: =L6*L3 -> 0
A10: PPR/PLR
A11: FGTS | B11: =IF(B4="CLT",B3*0.08*12,"") -> 0 | C11: =IF(C4="CLT",C3*0.08*12,"") | D11: =IF(D4="CLT",D3*0.08*12,"") | F11: =IF(F4="CLT",F3*0.08*12,"") -> 0 | G11: =IF(G4="CLT",G3*0.08*12,"") | H11: =IF(H4="CLT",H3*0.08*12,"") | J11: =IF(J4="CLT",J3*0.08*12,"") -> 0 | K11: =IF(K4="CLT",K3*0.08*12,"") | L11: =IF(L4="CLT",L3*0.08*12,"")
A12: ILP
A13: Previdência Privada
A14: Car Allowance
A15: Vale Combustível
A16: Auxílio Alimentação
A17: Auxílio Educação
A18: Auxilio Idiomas
A19: Plano de Saúde
A20: Hiring Bonus
A21: Set in Allowance
A22: Outros
A23: Tributação | B23: =IF(B4="CLT","27,5%",IF(B4="PJ","PREENCHER",IF(B4="Estatutário","27,5%",IF(B4="RSU","PREENCHER","0")))) -> 27,5% | C23: =IF(C4="CLT","27,5%",IF(C4="PJ","PREENCHER",IF(C4="Estatutário","27,5%",IF(C4="RSU","PREENCHER","0")))) -> PREENCHER | D23: =IF(D4="CLT","27,5%",IF(D4="PJ","PREENCHER",IF(D4="Estatutário","27,5%",IF(D4="RSU","PREENCHER","0")))) -> PREENCHER | F23: =IF(F4="CLT","27,5%",IF(F4="PJ","PREENCHER",IF(F4="Estatutário","27,5%",IF(F4="RSU","PREENCHER","0")))) -> 27,5% | G23: =IF(G4="CLT","27,5%",IF(G4="PJ","PREENCHER",IF(G4="Estatutário","27,5%",IF(G4="RSU","PREENCHER","0")))) -> PREENCHER | H23: =IF(H4="CLT","27,5%",IF(H4="PJ","PREENCHER",IF(H4="Estatutário","27,5%",IF(H4="RSU","PREENCHER","0")))) -> PREENCHER | J23: =IF(J4="CLT","27,5%",IF(J4="PJ","PREENCHER",IF(J4="Estatutário","27,5%",IF(J4="RSU","PREENCHER","0")))) -> 27,5% | K23: =IF(K4="CLT","27,5%",IF(K4="PJ","PREENCHER",IF(K4="Estatutário","27,5%",IF(K4="RSU","PREENCHER","0")))) -> PREENCHER | L23: =IF(L4="CLT","27,5%",IF(L4="PJ","PREENCHER",IF(L4="Estatutário","27,5%",IF(L4="RSU","PREENCHER","0")))) -> PREENCHER
A24: Remuneração/Ano - Bruto | B24: =SUM(B8:B22) -> 0 | C24: =SUM(C8:C22) -> 0 | D24: =SUM(D8:D22) -> 0 | F24: =SUM(F8:F22) -> 0 | G24: =SUM(G8:G22) -> 0 | H24: =SUM(H8:H22) -> 0 | J24: =SUM(J8:J22) -> 0 | K24: =SUM(K8:K22) -> 0 | L24: =SUM(L8:L22) -> 0
A25: Diferença Remuneração Bruta | C25: =C24-B24 -> 0 | D25: =D24-B24 -> 0 | G25: =G24-F24 -> 0 | H25: =H24-F24 -> 0 | K25: =K24-J24 -> 0 | L25: =L24-J24 -> 0
A26: Evolução Remuneração Bruta | C26: =C25/B24 -> #DIV/0! | D26: =D25/B24 -> #DIV/0! | G26: =G25/F24 -> #DIV/0! | H26: =H25/F24 -> #DIV/0! | K26: =K25/J24 -> #DIV/0! | L26: =L25/J24 -> #DIV/0!
A27: Remuneração/Ano - Líquida | B27: =SUM(B8:B10)*(1-B23)+SUM(B11:B22) -> 0 | C27: =SUM(C8:C10)*(1-C23)+SUM(C11:C22) -> #VALUE! | D27: =SUM(D8:D10)*(1-D23)+SUM(D11:D22) -> #VALUE! | F27: =SUM(F8:F10)*(1-F23)+SUM(F11:F22) -> 0 | G27: =SUM(G8:G10)*(1-G23)+SUM(G11:G22) -> #VALUE! | H27: =SUM(H8:H10)*(1-H23)+SUM(H11:H22) -> #VALUE! | J27: =SUM(J8:J10)*(1-J23)+SUM(J11:J22) -> 0 | K27: =SUM(K8:K10)*(1-K23)+SUM(K11:K22) -> #VALUE! | L27: =SUM(L8:L10)*(1-L23)+SUM(L11:L22) -> #VALUE!
A28: Diferença Remuneração Líquida | C28: =C27-B27 -> #VALUE! | D28: =D27-B27 -> #VALUE! | G28: =G27-F27 -> #VALUE! | H28: =H27-F27 -> #VALUE! | K28: =K27-J27 -> #VALUE! | L28: =L27-J27 -> #VALUE!
A29: Evolução Remuneração Líquida | C29: =C28/B27 -> #VALUE! | D29: =D28/B27 -> #VALUE! | G29: =G28/F27 -> #VALUE! | H29: =H28/F27 -> #VALUE! | K29: =K28/J27 -> #VALUE! | L29: =L28/J27 -> #VALUE!

Sheet Referências
B2: Nome Candidato 1 | C2: CANDIDATO 1 | D2: Nome Candidato 2 | E2: CANDIDATO 2 | F2: Nome Candidato 3 | G2: CANDIDATO 3 | H2: Nome Candidato 4 | I2: CANDIDATO 4
B3: Cargo | Empresa 1/1 | C3: (CARGO | EMPRESA) | D3: Cargo | Empresa 1/2 | E3: (CARGO | EMPRESA) | F3: Cargo | Empresa 1/3 | G3: (CARGO | EMPRESA) | H3: Cargo | Empresa 1/4 | I3: (CARGO | EMPRESA)
B4: Texto 1/1 | C4: (texto) | D4: Texto 1/2 | E4: (texto) | F4: Texto 1/3 | G4: (Texto) | H4: Texto 1/4 | I4: (Texto)
B5: Cargo | Empresa 2/1 | C5: (CARGO | EMPRESA) | D5: Cargo | Empresa 2/2 | E5: (CARGO | EMPRESA) | F5: Cargo | Empresa 2/3 | G5: (CARGO | EMPRESA) | H5: Cargo | Empresa 2/4 | I5: (CARGO | EMPRESA)
B6: Texto 2/1 | C6: (texto) | D6: Texto 2/2 | E6: (texto) | F6: Texto 2/3 | G6: (Texto) | H6: Texto 2/4 | I6: (Texto)
B7: Cargo | Empresa 3/1 | C7: (CARGO | EMPRESA) | D7: Cargo | Empresa 3/2 | E7: (CARGO | EMPRESA) | F7: Cargo | Empresa 3/3 | G7: (CARGO | EMPRESA) | H7: Cargo | Empresa 3/4 | I7: (CARGO | EMPRESA)
B8: Texto 3/1 | C8: (texto) | D8: Texto 3/2 | E8: (texto) | F8: Texto 3/3 | G8: (Texto) | H8: Texto 3/4 | I8: (Texto)

Sheet Analise de remuneração 
B2: ANÁLISE DE RISCO DE MOVIMENTAÇÃO E REMUNERAÇÃO
B3: Nome Candidato 1 | G3: Nome Candidato 2 | L3: Nome Candidato 3
B4: Base mensal | C4: Empregador | D4: Pretensão | E4: Cliente | G4: Base mensal | H4: Empregador | I4: Pretensão | J4: Cliente | L4: Base mensal | M4: Empregador | N4: Pretensão | O4: Cliente
B5: Salário base mês | G5: Salário base mês | L5: Salário base mês
B6: Modelo de Contrato | C6: PJ | D6: PJ | E6: CLT | G6: Modelo de Contrato | H6: CLT | I6: PJ | J6: RSU | L6: Modelo de Contrato | M6: CLT | N6: PJ | O6: RSU
B7: Multiplos de salário | C7: =IF(C6="CLT","13,33",IF(C6="PJ","12",IF(C6="Estatutário","12",IF(C6="RSU","12","NULL")))) -> 12 | D7: =IF(D6="CLT","13,33",IF(D6="PJ","12",IF(D6="Estatutário","12",IF(D6="RSU","12","NULL")))) -> 12 | E7: =IF(E6="CLT","13,33",IF(E6="PJ","12",IF(E6="Estatutário","12",IF(E6="RSU","12","NULL")))) -> 13,33 | G7: Multiplos de salário | H7: =IF(H6="CLT","13,33",IF(H6="PJ","12",IF(H6="Estatutário","12",IF(H6="RSU","12","NULL")))) -> 13,33 | I7: =IF(I6="CLT","13,33",IF(I6="PJ","12",IF(I6="Estatutário","12",IF(I6="RSU","12","NULL")))) -> 12 | J7: =IF(J6="CLT","13,33",IF(J6="PJ","12",IF(J6="Estatutário","12",IF(J6="RSU","12","NULL")))) -> 12 | L7: Multiplos de salário | M7: =IF(M6="CLT","13,33",IF(M6="PJ","12",IF(M6="Estatutário","12",IF(M6="RSU","12","NULL")))) -> 13,33 | N7: =IF(N6="CLT","13,33",IF(N6="PJ","12",IF(N6="Estatutário","12",IF(N6="RSU","12","NULL")))) -> 12 | O7: =IF(O6="CLT","13,33",IF(O6="PJ","12",IF(O6="Estatutário","12",IF(O6="RSU","12","NULL")))) -> 12
B8: Múltiplos de salários de bônus | G8: Múltiplos de salários de bônus | L8: Múltiplos de salários de bônus
B9: Base anual | G9: Base anual | L9: Base anual
B10: Remuneração fixa | C10: =C5*C7 -> 0 | D10: =D5*D7 -> 0 | E10: =E5*E7 -> 0 | G10: Remuneração fixa | H10: =H5*H7 -> 0 | I10: =I5*I7 -> 0 | J10: =J5*J7 -> 0 | L10: Remuneração fixa | M10: =M5*M7 -> 0 | N10: =N5*N7 -> 0 | O10: =O5*O7 -> 0
B11: Bônus | ICP | C11: =C8*C5 -> 0 | D11: =D8*D5 -> 0 | E11: =E8*E5 -> 0 | G11: Bônus | ICP | H11: =H8*H5 -> 0 | I11: =I8*I5 -> 0 | J11: =J8*J5 -> 0 | L11: Bônus | ICP | M11: =M8*M5 -> 0 | N11: =N8*N5 -> 0 | O11: =O8*O5 -> 0
B12: PPR/PLR | G12: PPR/PLR | L12: PPR/PLR
B13: FGTS | C13: =IF(C6="CLT",C5*0.08*12,"") | D13: =IF(D6="CLT",D5*0.08*12,"") | E13: =IF(E6="CLT",E5*0.08*12,"") -> 0 | G13: FGTS | H13: =IF(H6="CLT",H5*0.08*12,"") -> 0 | I13: =IF(I6="CLT",I5*0.08*12,"") | J13: =IF(J6="CLT",J5*0.08*12,"") | L13: FGTS | M13: =IF(M6="CLT",M5*0.08*12,"") -> 0 | N13: =IF(N6="CLT",N5*0.08*12,"") | O13: =IF(O6="CLT",O5*0.08*12,"")
B14: ILP | G14: ILP | L14: ILP
B15: Previdência Privada | G15: Previdência Privada | L15: Previdência Privada
B16: Car Allowance | G16: Car Allowance | L16: Car Allowance
B17: Vale Combustível | E17: =20*25*12 -> 6000 | G17: Vale Combustível | L17: Vale Combustível
B18: Auxílio Alimentação | G18: Auxílio Alimentação | L18: Auxílio Alimentação
B19: Auxílio Educação | G19: Auxílio Educação | L19: Auxílio Educação
B20: Auxilio Idiomas | G20: Auxilio Idiomas | L20: Auxilio Idiomas
B21: Plano de Saúde | G21: Plano de Saúde | L21: Plano de Saúde
B22: Hiring Bonus | G22: Hiring Bonus | L22: Hiring Bonus
B23: Set in Allowance | G23: Set in Allowance | L23: Set in Allowance
B24: Outros | G24: Outros | L24: Outros
B25: Tributação | C25: =IF(C6="CLT","27,5%",IF(C6="PJ","PREENCHER",IF(C6="Estatutário","27,5%",IF(C6="RSU","PREENCHER","0")))) -> PREENCHER | D25: =IF(D6="CLT","27,5%",IF(D6="PJ","PREENCHER",IF(D6="Estatutário","27,5%",IF(D6="RSU","PREENCHER","0")))) -> PREENCHER | E25: =IF(E6="CLT","27,5%",IF(E6="PJ","PREENCHER",IF(E6="Estatutário","27,5%",IF(E6="RSU","PREENCHER","0")))) -> 27,5% | G25: Tributação | H25: =IF(H6="CLT","27,5%",IF(H6="PJ","PREENCHER",IF(H6="Estatutário","27,5%",IF(H6="RSU","PREENCHER","0")))) -> 27,5% | I25: =IF(I6="CLT","27,5%",IF(I6="PJ","PREENCHER",IF(I6="Estatutário","27,5%",IF(I6="RSU","PREENCHER","0")))) -> PREENCHER | J25: =IF(J6="CLT","27,5%",IF(J6="PJ","PREENCHER",IF(J6="Estatutário","27,5%",IF(J6="RSU","PREENCHER","0")))) -> PREENCHER | L25: Tributação | M25: =IF(M6="CLT","27,5%",IF(M6="PJ","PREENCHER",IF(M6="Estatutário","27,5%",IF(M6="RSU","PREENCHER","0")))) -> 27,5% | N25: =IF(N6="CLT","27,5%",IF(N6="PJ","PREENCHER",IF(N6="Estatutário","27,5%",IF(N6="RSU","PREENCHER","0")))) -> PREENCHER | O25: =IF(O6="CLT","27,5%",IF(O6="PJ","PREENCHER",IF(O6="Estatutário","27,5%",IF(O6="RSU","PREENCHER","0")))) -> PREENCHER
B26: Remuneração/Ano - Bruto | C26: =SUM(C10:C24) -> 0 | D26: =SUM(D10:D24) -> 0 | E26: =SUM(E10:E24) -> 6000 | G26: Remuneração/Ano - Bruto | H26: =SUM(H10:H24) -> 0 | I26: =SUM(I10:I24) -> 0 | J26: =SUM(J10:J24) -> 0 | L26: Remuneração/Ano - Bruto | M26: =SUM(M10:M24) -> 0 | N26: =SUM(N10:N24) -> 0 | O26: =SUM(O10:O24) -> 0
B27: Diferença Remuneração Bruta | D27: =D26-C26 -> 0 | E27: =E26-C26 -> 6000 | G27: Diferença Remuneração Bruta | I27: =I26-H26 -> 0 | J27: =J26-H26 -> 0 | L27: Diferença Remuneração Bruta | N27: =N26-M26 -> 0 | O27: =O26-M26 -> 0
B28: Evolução Remuneração Bruta | D28: =D27/C26 -> #DIV/0! | E28: =E27/C26 -> #DIV/0! | G28: Evolução Remuneração Bruta | I28: =I27/H26 -> #DIV/0! | J28: =J27/H26 -> #DIV/0! | L28: Evolução Remuneração Bruta | N28: =N27/M26 -> #DIV/0! | O28: =O27/M26 -> #DIV/0!
B29: Remuneração/Ano - Líquida | C29: =SUM(C10:C12)*(1-C25)+SUM(C13:C24) -> #VALUE! | D29: =SUM(D10:D12)*(1-D25)+SUM(D13:D24) -> #VALUE! | E29: =SUM(E10:E12)*(1-E25)+SUM(E13:E24) -> 6000 | G29: Remuneração/Ano - Líquida | H29: =SUM(H10:H12)*(1-H25)+SUM(H13:H24) -> 0 | I29: =SUM(I10:I12)*(1-I25)+SUM(I13:I24) -> #VALUE! | J29: =SUM(J10:J12)*(1-J25)+SUM(J13:J24) -> #VALUE! | L29: Remuneração/Ano - Líquida | M29: =SUM(M10:M12)*(1-M25)+SUM(M13:M24) -> 0 | N29: =SUM(N10:N12)*(1-N25)+SUM(N13:N24) -> #VALUE! | O29: =SUM(O10:O12)*(1-O25)+SUM(O13:O24) -> #VALUE!
B30: Diferença Remuneração Líquida | D30: =D29-C29 -> #VALUE! | E30: =E29-C29 -> #VALUE! | G30: Diferença Remuneração Líquida | I30: =I29-H29 -> #VALUE! | J30: =J29-H29 -> #VALUE! | L30: Diferença Remuneração Líquida | N30: =N29-M29 -> #VALUE! | O30: =O29-M29 -> #VALUE!
B31: Evolução Remuneração Líquida | D31: =D30/C29 -> #VALUE! | E31: =E30/C29 -> #VALUE! | G31: Evolução Remuneração Líquida | I31: =I30/H29 -> #VALUE! | J31: =J30/H29 -> #VALUE! | L31: Evolução Remuneração Líquida | N31: =N30/M29 -> #VALUE! | O31: =O30/M29 -> #VALUE!
B33: Riscos | C33: Grau | D33: Descrição | G33: Riscos | H33: Grau | I33: Descrição | L33: Riscos | M33: Grau | N33: Descrição
B34: Pacote | C34: 0 | G34: Pacote | H34: 0 | L34: Pacote | M34: 0
B35: Mobilidade | C35: 0 | G35: Mobilidade | H35: 0 | L35: Mobilidade | M35: 0
B36: Motivação | C36: 0 | G36: Motivação | H36: 0 | L36: Motivação | M36: 0
B37: Contexto atual | C37: 0 | G37: Contexto atual | H37: 0 | L37: Contexto atual | M37: 0
B38: Suporte Financeiro | C38: 0 | G38: Suporte Financeiro | H38: 0 | L38: Suporte Financeiro | M38: 0
B39: Estrutura familiar | C39: 0 | G39: Estrutura familiar | H39: 0 | L39: Estrutura familiar | M39: 0
B40: Grau de risco | C40: =AVERAGE(C34:C39) -> 0 | G40: Grau de risco | H40: =AVERAGE(H34:H39) -> 0 | L40: Grau de risco | M40: =AVERAGE(M34:M39) -> 0
B42: CANDIDATO | C42: TOTAL CASH | D42: GRAU DE RISCO
B43: =B3 -> Nome Candidato 1 | C43: =C26 -> 0 | D43: =C40 -> 0
...

Sheet Tomada de Decisão
B1: TÍTULO | C1: COLAR AQUI
B2: [EMPRESA] - [POSIÇÃO]

Sheet -
A1: EMPRESA | B1: POSIÇÃO | C1: ESTRUTURA DA EMPRESA | D1: SETOR, CONCORRÊNCIA E DIFERENCIAIS COMPETITIVOS | E1: MOMENTO / CONTEXTO DA EMPRESA | F1: PRINCIPAIS DESAFIOS ATUAIS DA EMPRESA | G1: PRINCIPAIS OBJETIVOS E DESAFIOS DA VAGA | H1: REPORTE DIRETO | I1: EQUIPE | J1: LOCALIDADE | K1: MODELO DE CONTRATAÇÃO | L1: SALÁRIO FIXO MENSAL | M1: REMUNERAÇÃO VARIÁVEL | N1: EXPERIÊNCIA PROFISSIONAL IDEAL DO EXECUTIVO | O1: HISTÓRICO ACADÊMICO IDEAL DO EXECUTIVO | P1: CORE SKILL IDEAL 1 | Q1: CORE SKILL IDEAL 2 | R1: CORE SKILL IDEAL 3 | S1: REQUISITOS ESPECÍFICOS PARA O EXECUTIVO | T1: SHORTLIST 1 | U1: CANDIDATO 1 | V1: IDADE 1 | W1: POSIÇÃO ATUAL 1 | X1: LOCALIDADE 1 | Y1: HISTÓRICO ACADÊMICO 1 | Z1: EXPERIÊNCIA PROFISSIONAL 1 | AA1: PRINCIPAIS PROJETOS DA CARREIRA 1 | AB1: PACOTE DE REMUNERAÇÃO ATUAL 1 | AC1: CORE SKILLS 1 | AD1: MOTIVAÇÕES 1 | AE1: SHORTLIST 2 | AF1: CANDIDATO 2 | AG1: IDADE 2 | AH1: POSIÇÃO ATUAL 2 | AI1: LOCALIDADE 2 | AJ1: HISTÓRICO ACADÊMICO 2 | AK1: EXPERIÊNCIA PROFISSIONAL 2 | AL1: PRINCIPAIS PROJETOS DA CARREIRA 2 | AM1: PACOTE DE REMUNERAÇÃO ATUAL 2 | AN1: CORE SKILLS 2 | AO1: MOTIVAÇÕES 2 | AP1: SHORTLIST 3 | AQ1: CANDIDATO 3 | AR1: IDADE 3 | AS1: POSIÇÃO ATUAL 3 | AT1: LOCALIDADE 3 | AU1: HISTÓRICO ACADÊMICO 3 | AV1: EXPERIÊNCIA PROFISSIONAL 3 | AW1: PRINCIPAIS PROJETOS DA CARREIRA 3 | AX1: PACOTE DE REMUNERAÇÃO ATUAL 3 | AY1: CORE SKILLS 3 | AZ1: MOTIVAÇÕES 3 | BA1: SHORTLIST 4 | BB1: CANDIDATO 4 | BC1: IDADE 4 | BD1: POSIÇÃO ATUAL 4 | BE1: LOCALIDADE 4 | BF1: HISTÓRICO ACADÊMICO 4 | BG1: EXPERIÊNCIA PROFISSIONAL 4 | BH1: PRINCIPAIS PROJETOS DA CARREIRA 4 | BI1: PACOTE DE REMUNERAÇÃO ATUAL 4 | BJ1: CORE SKILLS 4 | BK1: MOTIVAÇÕES 4 | BL1: SHORTLIST 5 | BM1: CANDIDATO 5 | BN1: IDADE 5 | BO1: POSIÇÃO ATUAL 5 | BP1: LOCALIDADE 5 | BQ1: HISTÓRICO ACADÊMICO 5 | BR1: EXPERIÊNCIA PROFISSIONAL 5 | BS1: PRINCIPAIS PROJETOS DA CARREIRA 5 | BT1: PACOTE DE REMUNERAÇÃO ATUAL 5 | BU1: CORE SKILLS 5 | BV1: MOTIVAÇÕES 5 | BW1: SHORTLIST 6 | BX1: CANDIDATO 6 | BY1: IDADE 6 | BZ1: POSIÇÃO ATUAL 6 | CA1: LOCALIDADE 6 | CB1: HISTÓRICO ACADÊMICO 6 | CC1: EXPERIÊNCIA PROFISSIONAL 6 | CD1: PRINCIPAIS PROJETOS DA CARREIRA 6 | CE1: PACOTE DE REMUNERAÇÃO ATUAL 6 | CF1: CORE SKILLS 6 | CG1: MOTIVAÇÕES 6 | CH1: SHORTLIST 7 | CI1: CANDIDATO 7 | CJ1: IDADE 7 | CK1: POSIÇÃO ATUAL 7 | CL1: LOCALIDADE 7 | CM1: HISTÓRICO ACADÊMICO 7 | CN1: EXPERIÊNCIA PROFISSIONAL 7 | CO1: PRINCIPAIS PROJETOS DA CARREIRA 7 | CP1: PACOTE DE REMUNERAÇÃO ATUAL 7 | CQ1: CORE SKILLS 7 | CR1: MOTIVAÇÕES 7 | CS1: SHORTLIST 8 | CT1: CANDIDATO 8 | CU1: IDADE 8 | CV1: POSIÇÃO ATUAL 8 | CW1: LOCALIDADE 8 | CX1: HISTÓRICO ACADÊMICO 8 | CY1: EXPERIÊNCIA PROFISSIONAL 8 | CZ1: PRINCIPAIS PROJETOS DA CARREIRA 8 | DA1: PACOTE DE REMUNERAÇÃO ATUAL 8 | DB1: CORE SKILLS 8 | DC1: MOTIVAÇÕES 8 | DD1: SHORTLIST 9 | DE1: CANDIDATO 9 | DF1: IDADE 9 | DG1: POSIÇÃO ATUAL 9 | DH1: LOCALIDADE 9 | DI1: HISTÓRICO ACADÊMICO 9 | DJ1: EXPERIÊNCIA PROFISSIONAL 9 | DK1: PRINCIPAIS PROJETOS DA CARREIRA 9 | DL1: PACOTE DE REMUNERAÇÃO ATUAL 9 | DM1: CORE SKILLS 9 | DN1: MOTIVAÇÕES 9 | DO1: SHORTLIST 10 | DP1: CANDIDATO 10 | DQ1: IDADE 10 | DR1: POSIÇÃO ATUAL 10 | DS1: LOCALIDADE 10 | DT1: HISTÓRICO ACADÊMICO 10 | DU1: EXPERIÊNCIA PROFISSIONAL 10 | DV1: PRINCIPAIS PROJETOS DA CARREIRA 10 | DW1: PACOTE DE REMUNERAÇÃO ATUAL 10 | DX1: CORE SKILLS 10 | DY1: MOTIVAÇÕES 10 | DZ1: Nome Candidato 1 | EA1: Cargo | Empresa 1/1 | EB1: Texto 1/1 | EC1: Cargo | Empresa 2/1 | ED1: Texto 2/1 | EE1: Cargo | Empresa 3/1 | EF1: Texto 3/1 | EG1: Nome Candidato 2 | EH1: Cargo | Empresa 1/2 | EI1: Texto 1/2 | EJ1: Cargo | Empresa 2/2 | EK1: Texto 2/2 | EL1: Cargo | Empresa 3/2 | EM1: Texto 3/2 | EN1: Nome Candidato 3 | EO1: Cargo | Empresa 1/3 | EP1: Texto 1/3 | EQ1: Cargo | Empresa 2/3 | ER1: Texto 2/3 | ES1: Cargo | Empresa 3/3 | ET1: Texto 3/3 | EU1: Nome Candidato 4 | EV1: Cargo | Empresa 1/4 | EW1: Texto 1/4 | EX1: Cargo | Empresa 2/4 | EY1: Texto 2/4 | EZ1: Cargo | Empresa 3/4 | FA1: Texto 3/4
A2: =Alinhamento!C2 -> NOME EMPRESA | B2: =Alinhamento!D2 -> POSIÇÃO | C2: =Alinhamento!D3 | D2: =Alinhamento!D4 | E2: =Alinhamento!D5 | F2: =Alinhamento!D6 | G2: =Alinhamento!D7 | H2: =Alinhamento!D8 | I2: =Alinhamento!D9 | J2: =Alinhamento!D10 | K2: =Alinhamento!D11 | L2: =Alinhamento!D12 | M2: =Alinhamento!D13 | N2: =Alinhamento!D14 | O2: =Alinhamento!D15 | P2: =Alinhamento!D16 | Q2: =Alinhamento!D17 | R2: =Alinhamento!D18 | S2: =Alinhamento!D19 | T2: =Shortlist!B3 -> Candidato 1 | U2: =Shortlist!C3 -> Paulo Ricardo Dauinheimer Machado | V2: =Shortlist!D3 -> N/A | W2: =Shortlist!E3 -> Gerente de Operações | X2: =Shortlist!F3 -> N/A | Y2: =Shortlist!G3 -> N/A | Z2: =Shortlist!H3 -> META – Gerente de Operações (DEZ/2024 – ATUAL); SPACE7 DIGITAL – CEO e Founder (FEV/2023 – DEZ/2024); LINX – Gerente de Operações (JUN/2018 – FEV/2023); DCG – Gerente de Operações (DEZ/2015 – JUN/2018); EZ COMMERCE – Coordenador de Equipe (JAN/2015 – DEZ/2015); Stefanini (Estágio a Líder de Equipe): Cinco anos, saiu liderando 25 pessoas em suporte puro de TI Nível 2. | AA2: =Shortlist!I3 -> 1. Estruturação de Indicadores e KPIs do Zero: Na startup de e-commerce (EZ/DCG), implementou o Zendesk e criou métricas de performance e bases analíticas do zero, estruturando o suporte para o crescimento subsequente. 2. Recuperação do NPS: Coordenou um plano de ação colaborativo entre Operações e Produto após feedback negativo (devido à descontinuação de um produto), revertendo o NPS de um patamar negativo para 50-60 em cerca de um ano e meio. 3. Gestão de Crise e Liderança na Pandemia: Durante o crescimento de demanda do e-commerce, a equipe cresceu de 50 para 80 pessoas. Blindou o time, assumindo responsabilidades em reuniões de War Room. Foi premiado como "Líder do Ano" da Linx em 2021. | ... AD2: =Shortlist!L3 -> Busca uma oportunidade mais alinhada com sua visão cultural, diferente do perfil tradicional da Meta. Almeja desafios estratégicos em um cenário de crescimento exponencial e deseja participar ativamente das decisões, papel que exerceu anteriormente. | AE2: =#REF! -> #REF! | AF2: =#REF! -> #REF! | AG2: =#REF! -> #REF! | AH2: =#REF! -> #REF! | AI2: =#REF! -> #REF! | AJ2: =#REF! -> #REF! | AK2: =#REF! -> #REF! | AL2: =#REF! -> #REF! | ... AO2: =#REF! -> #REF! | AP2: =Shortlist!B4 -> Candidato 2 | AQ2: =Shortlist!C4 -> Saul Souza | AR2: =Shortlist!D4 -> 31 | AS2: =Shortlist!E4 -> Gerente de Tecnologia e Desenvolvimento (DI MARMORE) e Gerente de Suporte Técnico (ISYSTEMS) | AT2: =Shortlist!F4 -> Taboão da Serra / SP | AU2: =Shortlist!G4 -> PONTIFÍCIA UNIVERSIDADE CATÓLICA DO RS (PUCRS) – MBA em Gestão de Projetos (2025 – ATUAL); UNIVERSIDADE ANHEMBI MORUMBI (UAM) – Graduação em Gestão de TI (2019 – 2021) | AV2: =Shortlist!H4 -> DI MARMORE – Gerente de Tecnologia e Desenvolvimento (JUL/2025 – ATUAL); ISYSTEMS – Gerente de Suporte Técnico (DEZ/2023 – ATUAL); OMIE – Gerente de Suporte Técnico (DEZ/2017 – SET/2023) | AW2: =Shortlist!I4 -> 1. Restruturação da Área de Suporte na OMIE: Estruturou cargos (Estagiário, N1, N2, N3) e departamentos (Qualidade, Treinamento), escalando a operação de 20.000 para 70.000 chamados/mês e alcançando 98% de CSAT pelo terceiro ano consecutivo. 2. Criação do Departamento de Treinamento na OMIE: Implementou uma "universidade" de suporte para reduzir a rampagem do analista de 2 anos para 6 meses. 3. Transformação do Suporte e Aumento da Taxa de Uso na ISYSTEMS: Reformulou o suporte técnico, focando na taxa de uso do software de controle avançado. Resultado: Atingiu 79% de taxa de uso, o maior índice na história da empresa. | ... AZ2: =Shortlist!L4 -> Retornar à área de suporte em uma empresa em ascensão e forte crescimento (similar ao modelo da OMIE), que ofereça desafios transformacionais. Buscar um ambiente que proporcione oportunidades de aprendizado e proximidade com a liderança sênior. Disposto a realizar uma mudança familiar para o Rio Grande do Sul, caso a oportunidade seja atrativa. | BA2: =Shortlist!B5 | BB2: =Shortlist!C5 | BC2: =Shortlist!D5 | BD2: =Shortlist!E5 | BE2: =Shortlist!F5 | BF2: =Shortlist!G5 | BG2: =Shortlist!H5 | BH2: =Shortlist!I5 | ... BK2: =Shortlist!L5 | BL2: =Shortlist!B6 | BM2: =Shortlist!C6 | BN2: =Shortlist!D6 | BO2: =Shortlist!E6 | BP2: =Shortlist!F6 | BQ2: =Shortlist!G6 | BR2: =Shortlist!H6 | BS2: =Shortlist!I6 | ... BV2: =Shortlist!L6 | BW2: =Shortlist!B7 | BX2: =Shortlist!C7 | BY2: =Shortlist!D7 | BZ2: =Shortlist!E7 | CA2: =Shortlist!F7 | CB2: =Shortlist!G7 | CC2: =Shortlist!H7 | CD2: =Shortlist!I7 | ... CG2: =Shortlist!L7 | CH2: =Shortlist!B8 | CI2: =Shortlist!C8 | CJ2: =Shortlist!D8 | CK2: =Shortlist!E8 | CL2: =Shortlist!F8 | CM2: =Shortlist!G8 | CN2: =Shortlist!H8 | CO2: =Shortlist!I8 | ... CR2: =Shortlist!L8 | CS2: =Shortlist!B9 | CT2: =Shortlist!C9 | CU2: =Shortlist!D9 | CV2: =Shortlist!E9 | CW2: =Shortlist!F9 | CX2: =Shortlist!G9 | CY2: =Shortlist!H9 | CZ2: =Shortlist!I9 | ... DC2: =Shortlist!L9 | DD2: =Shortlist!B10 | DE2: =Shortlist!C10 | DF2: =Shortlist!D10 | DG2: =Shortlist!E10 | DH2: =Shortlist!F10 | DI2: =Shortlist!G10 | DJ2: =Shortlist!H10 | DK2: =Shortlist!I10 | ... DN2: =Shortlist!L10 | DO2: =Shortlist!B11 | DP2: =Shortlist!C11 | DQ2: =Shortlist!D11 | DR2: =Shortlist!E11 | DS2: =Shortlist!F11 | DT2: =Shortlist!G11 | DU2: =Shortlist!H11 | DV2: =Shortlist!I11 | ... DY2: =Shortlist!L11 | DZ2: ='Referências'!C2 -> CANDIDATO 1 | EA2: ='Referências'!C3 -> (CARGO | EMPRESA) | EB2: ='Referências'!C4 -> (texto) | EC2: ='Referências'!C5 -> (CARGO | EMPRESA) | ED2: ='Referências'!C6 -> (texto) | EE2: ='Referências'!C7 -> (CARGO | EMPRESA) | EF2: ='Referências'!C8 -> (texto) | EG2: ='Referências'!E2 -> CANDIDATO 2 | EH2: ='Referências'!E3 -> (CARGO | EMPRESA) | EI2: ='Referências'!E4 -> (texto) | EJ2: ='Referências'!E5 -> (CARGO | EMPRESA) | EK2: ='Referências'!E6 -> (texto) | EL2: ='Referências'!E7 -> (CARGO | EMPRESA) | EM2: ='Referências'!E8 -> (texto) | EN2: ='Referências'!G2 -> CANDIDATO 3 | EO2: ='Referências'!G3 -> (CARGO | EMPRESA) | EP2: ='Referências'!G4 -> (Texto) | EQ2: ='Referências'!G5 -> (CARGO | EMPRESA) | ER2: ='Referências'!G6 -> (Texto) | ES2: ='Referências'!G7 -> (CARGO | EMPRESA) | ET2: ='Referências'!G8 -> (Texto) | EU2: ='Referências'!I2 -> CANDIDATO 4 | EV2: ='Referências'!I3 -> (CARGO | EMPRESA) | EW2: ='Referências'!I4 -> (Texto) | EX2: ='Referências'!I5 -> (CARGO | EMPRESA) | EY2: ='Referências'!I6 -> (Texto) | EZ2: ='Referências'!I7 -> (CARGO | EMPRESA) | FA2: ='Referências'!I8 -> (Texto)
